Workbook

Sheet RAW DATA
A1: NAME | B1: SURNAME | C1: SEX | D1: DOB | E1: AGE | F1: GRADE | G1: TEST DATE YEAR | H1: TEST DATE MONTH | I1: TEST TERM | J1: WINTER SPORT 1 | K1: WINTER SPORT 1- TEAM | L1: WINTER SPORT 1 - POSITION | M1: WINTER SPORT 2 | N1: WINTER SPORT 2 - TEAM | O1: WINTER SPORT 2 - POSITION | P1: SUMMER SPORT 1 | Q1: SUMMER SPORT 1 - TEAM | R1: SUMMER SPORT 1 - POSITION | S1: SEATED HEIGHT | T1: STANDING HEIGHT | U1: WEIGHT | V1: TBW | W1: BFM (kg) | X1: FFM (kg) | Y1: SMM (kg) | Z1: BMI | AA1: %BF | AB1: FFM (kg) (right leg) | AC1: FFM% (right leg) | AD1: FFM (kg) (left leg) | AE1: FFM% (left leg) | AF1: BFM (kg) (right leg) | AG1: BFM% (right leg) | AH1: BFM (kg) (left leg) | AI1: BFM% (left leg) | AJ1: 20kHz RL impedance | AK1: 20kHz LL impedance | AL1: 100kHz RL impedance | AM1: 100kHz LL impedance | AN1: GROWTH SCORE | AO1: WHR | AP1: SMI | AQ1: Stiff arm [Height] | AR1: Stiff arm [Flight-Time] | AS1: Counter-Movement-Jump [Height] | AT1: Counter-Movement-Jump [Flight-Time] | AU1: Single Leg Counter-Movement-Jump (L) [Height] | AV1: Single Leg Counter-Movement-Jump (L) Flight-Time | AW1: Single Leg Counter-Movement-Jump (R) Height | AX1: Single Leg Counter-Movement-Jump (R) Flight-Time | AY1: Stiff arm Peak Anaerobic Power (W/kg) (Sayers) | AZ1: Result based on NORM | BA1: CMJ Peak Anaerobic Power (W/kg) (Sayers) | BB1: Result based on NORM | BC1: CMJ LEFT Peak Anaerobic Power (W/kg) (Sayers) | BD1: Result based on NORM | BE1: CMJ RIGHT Peak Anaerobic Power (W/kg) (Sayers) | BF1: Result based on NORM | BG1: Sit (cm) | BH1: Reach (cm) | BI1: Flexibility | BJ1: Result based on NORM | BK1: K2W (L) | BL1: Result based on NORM | BM1: K2W (R) | BN1: Result based on NORM | BO1: MID THIGH LEFT [cm] | BP1: MID THIGH RIGHT [cm] | BQ1: Anterior (L) | BR1: Posterolateral (L) | BS1: Posteromedial (L) | BT1: Anterior (R) | BU1: Posterolateral (R) | BV1: Posteromedial (R) | BW1: Composite score LEFT (%) | BX1: Result based on NORM | BY1: Composite score RIGHT (%) | BZ1: Result based on NORM | CA1: 1-min sit up | CB1: Result based on NORM | CC1: 2-min Sit-ups | CD1: Result based on NORM | CE1: 1-min push up | CF1: Result based on NORM | CG1: Illinois (L) sec | CH1: Result based on NORM | CI1: Illinois (R) sec | CJ1: Result based on NORM | CK1: 10m sprint TIME [sec] | CL1: 10m sprint SPEED [m/s] | CM1: Result based on NORM | CN1: 40m sprint TIME (sec) | CO1: 40m sprint SPEED (m/s) | CP1: Result based on NORM | CQ1: BLEEP | CR1: Result based on NORM | CS1: Beep test score LEVEL | CT1: Beep test score SHUTTLE | CU1: Distance Run | CV1: Result based on NORM | CW1: VO2MAX
A2: Waggie | B2: Aaishah | C2: Female | D2: 40889 | F2: 9P | G2: 2026 | I2: 2 | J2: Netball | K2: U/15 D | S2: 81.3 | T2: 154.9 | U2: 62.5 | V2: 29.5 | W2: 22.2 | X2: 40.4 | Y2: 22 | AA2: 35.5 | AB2: 5.67 | AC2: 95.7 | AD2: 5.7 | AE2: 96.2 | AF2: 3.3 | AG2: 187 | AH2: 3.3 | AI2: 186.8 | AJ2: 289.8 | AK2: 285.6 | AL2: 255.9 | AM2: 252.3 | AN2: 70 | AQ2: 19.8 | AR2: 0.402 | AS2: 17.2 | AT2: 0.375 | AU2: 6.4 | AV2: 0.229 | AW2: 4.4 | AX2: 0.19 | AY2: =IF(OR(ISBLANK(U2), ISBLANK(AQ2)), "Incomplete", (60.7*AQ2)+(45.3*U2)-2055) -> 1978.11 | BA2: =IF(OR(ISBLANK(U2), ISBLANK(AS2)), "Incomplete", (60.7*AS2)+(45.3*U2)-2055) -> 1820.29 | BC2: =IF(OR(ISBLANK(U2), ISBLANK(AU2)), "Incomplete", (60.7*AU2)+(45.3*U2)-2055) -> 1164.73 | BE2: =IF(OR(ISBLANK(U2), ISBLANK(AW2)), "Incomplete", (60.7*AW2)+(45.3*U2)-2055) -> 1043.33 | BG2: 7.2 | BH2: 27.5 | BI2: =IF(OR(ISBLANK(BG2), ISBLANK(BH2)),"Incomplete",(SUM(BH2-BG2))) -> 20.3 | BK2: 7 | BM2: 5.5 | BO2: 52 | BP2: 53 | BQ2: 59 | BR2: 74 | BS2: 73 | BT2: 67 | BU2: 70 | BV2: 69 | BW2: =IFERROR(SUM(BQ2+BR2+BS2)/(3*(T2-S2))*100, "Incomplete") -> 93.297101 | BX2: =_xlfn.XLOOKUP(BW2,'Normative data'!$V$2:$V$6,'Normative data'!$W$2:$W$6,"Not Found",-1) -> High risk | BY2: =IFERROR(SUM(BT2+BU2+BV2)/(3*(T2-S2))*100, "Incomplete") -> 93.297101 | BZ2: =_xlfn.XLOOKUP(BY2,'Normative data'!$V$3:$V$6,'Normative data'!$W$3:$W$6,"Not Found",-1) -> High risk | CA2: 29 | CE2: 27 | CH2: =_xlfn.XLOOKUP(CG2, 'Normative data'!$S$9:$S$15,'Normative data'!$T$9:$T$15,"Not Found",-1) -> not completed | CJ2: =_xlfn.XLOOKUP(CI2, 'Normative data'!$S$9:$S$15, 'Normative data'!$T$9:$T$15, "Not Found", -1) -> not completed | CK2: 2.08 | CL2: 4.81 | CN2: 6.57 | CO2: 7.61 | CR2: {=IF(OR(ISBLANK(E2),ISBLANK(CQ2)),"Incomplete",_xlfn.XLOOKUP(CQ2,_xlfn.XLOOKUP(E2,'Normative data'!$Y$3:$Y$6,'Normative data'!$Z$3:$AG$6,,-1),'Normative data'!$Z$2:$AG$2,"Not Found",-1))} -> Incomplete | CU2: {=_xlfn.XLOOKUP(CS2&CT2,(VLOOKUP!$A$3:$A$250)&(VLOOKUP!$B$3:$B$250),VLOOKUP!$C$3:$C$250,"Incomplete",-1)} -> Incomplete | CV2: {=_xlfn.XLOOKUP(CU2, _xlfn.XLOOKUP(E2, 'Normative data'!$Y$11:$Y$14, 'Normative data'!$Z$11:$AG$14, ,-1), 'Normative data'!$Z$10:$AG$10, "Not Found", -1)} -> Excellent | CW2: {=IF(OR(ISBLANK(CS2),ISBLANK(CT2)),"Incomplete",_xlfn.XLOOKUP(CS2&CT2,VLOOKUP!$A$4:$A$250&VLOOKUP!$B$4:$B$250,VLOOKUP!$D$4:$D$250,"0"))} -> Incomplete
A3: Attenborough | B3: Abigail | C3: Female | D3: 40717 | E3: 14.9 | F3: 9E | G3: 2026 | I3: 2 | J3: Netball | K3: U/15 E | S3: 89.9 | T3: 172.6 | U3: 63.9 | V3: 33.5 | W3: 18.1 | X3: 45.8 | Y3: 25.1 | Z3: 21.4 | AA3: 28.3 | AB3: 8.11 | AC3: 109.8 | AD3: 8.09 | AE3: 109.6 | AF3: 3.3 | AG3: 120.3 | AH3: 3.3 | AI3: 120.3 | AJ3: 269.1 | AK3: 269.5 | AL3: 241.2 | AM3: 240.3 | AN3: 99 | AO3: 0.79 | AP3: 6.7 | AQ3: 22 | AR3: 0.424 | AS3: 26.5 | AT3: 0.465 | AU3: 14.7 | AV3: 0.346 | AW3: 10.7 | AX3: 0.295 | AY3: =IF(OR(ISBLANK(U3), ISBLANK(AQ3)), "Incomplete", (60.7*AQ3)+(45.3*U3)-2055) -> 2175.07 | BA3: =IF(OR(ISBLANK(U3), ISBLANK(AS3)), "Incomplete", (60.7*AS3)+(45.3*U3)-2055) -> 2448.22 | BC3: =IF(OR(ISBLANK(U3), ISBLANK(AU3)), "Incomplete", (60.7*AU3)+(45.3*U3)-2055) -> 1731.96 | BE3: =IF(OR(ISBLANK(U3), ISBLANK(AW3)), "Incomplete", (60.7*AW3)+(45.3*U3)-2055) -> 1489.16 | BG3: 9.6 | BH3: 43.1 | BI3: =IF(OR(ISBLANK(BG3), ISBLANK(BH3)),"Incomplete",(SUM(BH3-BG3))) -> 33.5 | BO3: 48.3 | BP3: 48.3 | BQ3: 89 | BR3: 100 | BS3: 94 | BT3: 80 | BU3: 105 | BV3: 90 | BW3: =IFERROR(SUM(BQ3+BR3+BS3)/(3*(T3-S3))*100, "Incomplete") -> 114.06691 | BX3: =_xlfn.XLOOKUP(BW3,'Normative data'!$V$2:$V$6,'Normative data'!$W$2:$W$6,"Not Found",-1) -> Low risk | BY3: =IFERROR(SUM(BT3+BU3+BV3)/(3*(T3-S3))*100, "Incomplete") -> 110.8424 | BZ3: =_xlfn.XLOOKUP(BY3,'Normative data'!$V$3:$V$6,'Normative data'!$W$3:$W$6,"Not Found",-1) -> Low risk | CA3: 32 | CE3: 13 | CH3: =_xlfn.XLOOKUP(CG3, 'Normative data'!$S$9:$S$15,'Normative data'!$T$9:$T$15, "Not Found", -1) -> not completed | CJ3: =_xlfn.XLOOKUP(CI3, 'Normative data'!$S$9:$S$15, 'Normative data'!$T$9:$T$15, "Not Found", -1) -> not completed | CQ3: 5.8 | CR3: {=IF(OR(ISBLANK(E3),ISBLANK(CQ3)),"Incomplete",_xlfn.XLOOKUP(CQ3,_xlfn.XLOOKUP(E3,'Normative data'!$Y$3:$Y$6,'Normative data'!$Z$3:$AG$6,,-1),'Normative data'!$Z$2:$AG$2,"Not Found",-1))} -> Fair | CS3: 5 | CT3: 8 | CU3: {=_xlfn.XLOOKUP(CS3&CT3,(VLOOKUP!$A$3:$A$250)&(VLOOKUP!$B$3:$B$250),VLOOKUP!$C$3:$C$250,"Incomplete",-1)} -> 800 | CV3: {=_xlfn.XLOOKUP(CU3, _xlfn.XLOOKUP(E3, 'Normative data'!$Y$11:$Y$14, 'Normative data'!$Z$11:$AG$14, ,-1), 'Normative data'!$Z$10:$AG$10, "Not Found", -1)} -> Fair | CW3: {=IF(OR(ISBLANK(CS3),ISBLANK(CT3)),"Incomplete",_xlfn.XLOOKUP(CS3&CT3,VLOOKUP!$A$4:$A$250&VLOOKUP!$B$4:$B$250,VLOOKUP!$D$4:$D$250,"0"))} -> 33
A4: Bottger | B4: Abigail | C4: Female | F4: 12 | G4: 2026 | I4: 2 | J4: Netball | K4: 2nd | AY4: =IF(OR(ISBLANK(U4), ISBLANK(AQ4)), "Incomplete", (60.7*AQ4)+(45.3*U4)-2055) -> Incomplete | BA4: =IF(OR(ISBLANK(U4), ISBLANK(AS4)), "Incomplete", (60.7*AS4)+(45.3*U4)-2055) -> Incomplete | BC4: =IF(OR(ISBLANK(U4), ISBLANK(AU4)), "Incomplete", (60.7*AU4)+(45.3*U4)-2055) -> Incomplete | BE4: =IF(OR(ISBLANK(U4), ISBLANK(AW4)), "Incomplete", (60.7*AW4)+(45.3*U4)-2055) -> Incomplete | BI4: =IF(OR(ISBLANK(BG4), ISBLANK(BH4)),"Incomplete",(SUM(BH4-BG4))) -> Incomplete | BW4: =IFERROR(SUM(BQ4+BR4+BS4)/(3*(T4-S4))*100, "Incomplete") -> Incomplete | BX4: =_xlfn.XLOOKUP(BW4,'Normative data'!$V$2:$V$6,'Normative data'!$W$2:$W$6,"Not Found",-1) -> Very low risk | BY4: =IFERROR(SUM(BT4+BU4+BV4)/(3*(T4-S4))*100, "Incomplete") -> Incomplete | BZ4: =_xlfn.XLOOKUP(BY4,'Normative data'!$V$3:$V$6,'Normative data'!$W$3:$W$6,"Not Found",-1) -> Very low risk | CH4: =_xlfn.XLOOKUP(CG4, 'Normative data'!$S$9:$S$15,'Normative data'!$T$9:$T$15, "Not Found", -1) -> not completed | CJ4: =_xlfn.XLOOKUP(CI4, 'Normative data'!$S$9:$S$15, 'Normative data'!$T$9:$T$15, "Not Found", -1) -> not completed | CQ4: 8.4 | CR4: {=IF(OR(ISBLANK(E4),ISBLANK(CQ4)),"Incomplete",_xlfn.XLOOKUP(CQ4,_xlfn.XLOOKUP(E4,'Normative data'!$Y$3:$Y$6,'Normative data'!$Z$3:$AG$6,,-1),'Normative data'!$Z$2:$AG$2,"Not Found",-1))} -> Incomplete | CS4: 8 | CT4: 4 | CU4: {=_xlfn.XLOOKUP(CS4&CT4,(VLOOKUP!$A$3:$A$250)&(VLOOKUP!$B$3:$B$250),VLOOKUP!$C$3:$C$250,"Incomplete",-1)} -> 1300 | CV4: {=_xlfn.XLOOKUP(CU4, _xlfn.XLOOKUP(E4, 'Normative data'!$Y$11:$Y$14, 'Normative data'!$Z$11:$AG$14, ,-1), 'Normative data'!$Z$10:$AG$10, "Not Found", -1)} -> Average | CW4: {=IF(OR(ISBLANK(CS4),ISBLANK(CT4)),"Incomplete",_xlfn.XLOOKUP(CS4&CT4,VLOOKUP!$A$4:$A$250&VLOOKUP!$B$4:$B$250,VLOOKUP!$D$4:$D$250,"0"))} -> 41
A5: de Coning | B5: Abigail | C5: Female | D5: 41166 | F5: 8A | G5: 2026 | I5: 2 | S5: 84.2 | T5: 165.9 | U5: 49.8 | V5: 30.3 | W5: 8.3 | X5: 41.5 | Y5: 22.6 | Z5: 18.1 | AA5: 16.7 | AB5: 6.59 | AC5: 114.4 | AD5: 6.63 | AE5: 115.1 | AF5: 1.5 | AG5: 60 | AH5: 1.5 | AI5: 60.1 | AJ5: 307 | AK5: 302.6 | AL5: 273.8 | AM5: 269.6 | AN5: 99 | AO5: 0.78 | AP5: 6.1 | AY5: =IF(OR(ISBLANK(U5), ISBLANK(AQ5)), "Incomplete", (60.7*AQ5)+(45.3*U5)-2055) -> Incomplete | BA5: =IF(OR(ISBLANK(U5), ISBLANK(AS5)), "Incomplete", (60.7*AS5)+(45.3*U5)-2055) -> Incomplete | BC5: =IF(OR(ISBLANK(U5), ISBLANK(AU5)), "Incomplete", (60.7*AU5)+(45.3*U5)-2055) -> Incomplete | BE5: =IF(OR(ISBLANK(U5), ISBLANK(AW5)), "Incomplete", (60.7*AW5)+(45.3*U5)-2055) -> Incomplete | BG5: 19 | BH5: 60.7 | BI5: =IF(OR(ISBLANK(BG5), ISBLANK(BH5)),"Incomplete",(SUM(BH5-BG5))) -> 41.7 | BK5: 9 | BM5: 9.5 | BO5: 45.5 | BP5: 47.5 | BQ5: 75 | BR5: 80 | BS5: 74 | BT5: 80 | BU5: 78 | BV5: 79 | BW5: =IFERROR(SUM(BQ5+BR5+BS5)/(3*(T5-S5))*100, "Incomplete") -> 93.431253 | BX5: =_xlfn.XLOOKUP(BW5,'Normative data'!$V$2:$V$6,'Normative data'!$W$2:$W$6,"Not Found",-1) -> High risk | BY5: =IFERROR(SUM(BT5+BU5+BV5)/(3*(T5-S5))*100, "Incomplete") -> 96.695226 | BZ5: =_xlfn.XLOOKUP(BY5,'Normative data'!$V$3:$V$6,'Normative data'!$W$3:$W$6,"Not Found",-1) -> Low risk | CA5: 35 | CE5: 21 | CH5: =_xlfn.XLOOKUP(CG5, 'Normative data'!$S$9:$S$15,'Normative data'!$T$9:$T$15, "Not Found", -1) -> not completed | CJ5: =_xlfn.XLOOKUP(CI5, 'Normative data'!$S$9:$S$15, 'Normative data'!$T$9:$T$15, "Not Found", -1) -> not completed | CK5: 1.99 | CL5: 5.03 | CN5: 6.33 | CO5: 7.9 | CR5: {=IF(OR(ISBLANK(E5),ISBLANK(CQ5)),"Incomplete",_xlfn.XLOOKUP(CQ5,_xlfn.XLOOKUP(E5,'Normative data'!$Y$3:$Y$6,'Normative data'!$Z$3:$AG$6,,-1),'Normative data'!$Z$2:$AG$2,"Not Found",-1))} -> Incomplete | CU5: {=_xlfn.XLOOKUP(CS5&CT5,(VLOOKUP!$A$3:$A$250)&(VLOOKUP!$B$3:$B$250),VLOOKUP!$C$3:$C$250,"Incomplete",-1)} -> Incomplete | CV5: {=_xlfn.XLOOKUP(CU5, _xlfn.XLOOKUP(E5, 'Normative data'!$Y$11:$Y$14, 'Normative data'!$Z$11:$AG$14, ,-1), 'Normative data'!$Z$10:$AG$10, "Not Found", -1)} -> Excellent | CW5: {=IF(OR(ISBLANK(CS5),ISBLANK(CT5)),"Incomplete",_xlfn.XLOOKUP(CS5&CT5,VLOOKUP!$A$4:$A$250&VLOOKUP!$B$4:$B$250,VLOOKUP!$D$4:$D$250,"0"))} -> Incomplete
A6: Jacobs | B6: Abigail | C6: Female | D6: 40270 | F6: 10E | G6: 2026 | I6: 2 | J6: Hockey | K6: 1st | L6: Defender | S6: 89.9 | T6: 171.9 | U6: 68 | V6: 41.4 | W6: 11.7 | X6: 56.3 | Y6: 31.5 | Z6: 22.8 | AA6: 17.3 | AB6: 8.43 | AC6: 111.7 | AD6: 8.38 | AE6: 111 | AF6: 1.8 | AG6: 65.6 | AH6: 1.8 | AI6: 65.4 | AJ6: 269.1 | AK6: 271.5 | AL6: 237.5 | AM6: 239 | AN6: 117 | AO6: 0.82 | AP6: 7.6 | AQ6: 26.2 | AR6: 0.462 | AS6: 26.7 | AT6: 0.467 | AU6: 13.8 | AV6: 0.336 | AW6: 12.5 | AX6: 0.319 | AY6: =IF(OR(ISBLANK(U6), ISBLANK(AQ6)), "Incomplete", (60.7*AQ6)+(45.3*U6)-2055) -> 2615.74 | BA6: =IF(OR(ISBLANK(U6), ISBLANK(AS6)), "Incomplete", (60.7*AS6)+(45.3*U6)-2055) -> 2646.09 | BC6: =IF(OR(ISBLANK(U6), ISBLANK(AU6)), "Incomplete", (60.7*AU6)+(45.3*U6)-2055) -> 1863.06 | BE6: =IF(OR(ISBLANK(U6), ISBLANK(AW6)), "Incomplete", (60.7*AW6)+(45.3*U6)-2055) -> 1784.15 | BG6: 11.4 | BH6: 50.4 | BI6: =IF(OR(ISBLANK(BG6), ISBLANK(BH6)),"Incomplete",(SUM(BH6-BG6))) -> 39 | BK6: 13.5 | BM6: 13 | BO6: 49 | BP6: 50 | BQ6: 84 | BR6: 80 | BS6: 70 | BT6: 80 | BU6: 83 | BV6: 74 | BW6: =IFERROR(SUM(BQ6+BR6+BS6)/(3*(T6-S6))*100, "Incomplete") -> 95.121951 | BX6: =_xlfn.XLOOKUP(BW6,'Normative data'!$V$2:$V$6,'Normative data'!$W$2:$W$6,"Not Found",-1) -> High risk | BY6: =IFERROR(SUM(BT6+BU6+BV6)/(3*(T6-S6))*100, "Incomplete") -> 96.341463 | BZ6: =_xlfn.XLOOKUP(BY6,'Normative data'!$V$3:$V$6,'Normative data'!$W$3:$W$6,"Not Found",-1) -> Low risk | CA6: 42 | CE6: 34 | CG6: 18.02 | CH6: =_xlfn.XLOOKUP(CG6, 'Normative data'!$S$9:$S$15,'Normative data'!$T$9:$T$15, "Not Found", -1) -> Average | CI6: 17.67 | CJ6: =_xlfn.XLOOKUP(CI6, 'Normative data'!$S$9:$S$15, 'Normative data'!$T$9:$T$15, "Not Found", -1) -> Above Average | CK6: 2.16 | CL6: 4.63 | CN6: 6.58 | CO6: 7.6 | CQ6: 7.7 | CR6: {=IF(OR(ISBLANK(E6),ISBLANK(CQ6)),"Incomplete",_xlfn.XLOOKUP(CQ6,_xlfn.XLOOKUP(E6,'Normative data'!$Y$3:$Y$6,'Normative data'!$Z$3:$AG$6,,-1),'Normative data'!$Z$2:$AG$2,"Not Found",-1))} -> Incomplete | CS6: 7 | CT6: 7 | CU6: {=_xlfn.XLOOKUP(CS6&CT6,(VLOOKUP!$A$3:$A$250)&(VLOOKUP!$B$3:$B$250),VLOOKUP!$C$3:$C$250,"Incomplete",-1)} -> 1160 | CV6: {=_xlfn.XLOOKUP(CU6, _xlfn.XLOOKUP(E6, 'Normative data'!$Y$11:$Y$14, 'Normative data'!$Z$11:$AG$14, ,-1), 'Normative data'!$Z$10:$AG$10, "Not Found", -1)} -> Average | CW6: {=IF(OR(ISBLANK(CS6),ISBLANK(CT6)),"Incomplete",_xlfn.XLOOKUP(CS6&CT6,VLOOKUP!$A$4:$A$250&VLOOKUP!$B$4:$B$250,VLOOKUP!$D$4:$D$250,"0"))} -> 39
A7: Petersen | B7: Abigail | C7: Female | D7: 40549 | E7: 14.8 | F7: 9A | G7: 2026 | I7: 2 | J7: Hockey | K7: U/16 C | S7: 84.6 | T7: 163.3 | U7: 67.4 | V7: 32 | W7: 23.5 | X7: 43.9 | Y7: 24 | Z7: 25.3 | AA7: 34.9 | AB7: 6.45 | AC7: 92.4 | AD7: 6.46 | AE7: 92.6 | AF7: 3.5 | AG7: 141.1 | AH7: 3.5 | AI7: 140.8 | AJ7: 313.1 | AK7: 310.4 | AL7: 279.4 | AM7: 277.7 | AN7: 83 | AO7: 0.92 | AP7: 6.5 | AQ7: 21.4 | AR7: 0.418 | AS7: 21.3 | AT7: 0.417 | AU7: 7.1 | AV7: 0.24 | AW7: 7.1 | AX7: 0.24 | AY7: =IF(OR(ISBLANK(U7), ISBLANK(AQ7)), "Incomplete", (60.7*AQ7)+(45.3*U7)-2055) -> 2297.2 | BA7: =IF(OR(ISBLANK(U7), ISBLANK(AS7)), "Incomplete", (60.7*AS7)+(45.3*U7)-2055) -> 2291.13 | BC7: =IF(OR(ISBLANK(U7), ISBLANK(AU7)), "Incomplete", (60.7*AU7)+(45.3*U7)-2055) -> 1429.19 | BE7: =IF(OR(ISBLANK(U7), ISBLANK(AW7)), "Incomplete", (60.7*AW7)+(45.3*U7)-2055) -> 1429.19 | BG7: 14.5 | BH7: 35 | BI7: =IF(OR(ISBLANK(BG7), ISBLANK(BH7)),"Incomplete",(SUM(BH7-BG7))) -> 20.5 | BK7: 9.5 | BM7: 8 | BO7: 53 | BP7: 52.5 | BQ7: 82 | BR7: 85 | BS7: 72 | BT7: 81 | BU7: 79 | BV7: 78 | BW7: =IFERROR(SUM(BQ7+BR7+BS7)/(3*(T7-S7))*100, "Incomplete") -> 101.22829 | BX7: =_xlfn.XLOOKUP(BW7,'Normative data'!$V$2:$V$6,'Normative data'!$W$2:$W$6,"Not Found",-1) -> Low risk | BY7: =IFERROR(SUM(BT7+BU7+BV7)/(3*(T7-S7))*100, "Incomplete") -> 100.80474 | BZ7: =_xlfn.XLOOKUP(BY7,'Normative data'!$V$3:$V$6,'Normative data'!$W$3:$W$6,"Not Found",-1) -> Low risk | CA7: 30 | CE7: 20 | CG7: 19.68 | CH7: =_xlfn.XLOOKUP(CG7, 'Normative data'!$S$9:$S$15,'Normative data'!$T$9:$T$15, "Not Found", -1) -> Average | CI7: 19.49 | CJ7: =_xlfn.XLOOKUP(CI7, 'Normative data'!$S$9:$S$15, 'Normative data'!$T$9:$T$15, "Not Found", -1) -> Average | CK7: 2.3 | CL7: 4.35 | CN7: 7.21 | CO7: 6.93 | CQ7: 3.6 | CR7: {=IF(OR(ISBLANK(E7),ISBLANK(CQ7)),"Incomplete",_xlfn.XLOOKUP(CQ7,_xlfn.XLOOKUP(E7,'Normative data'!$Y$3:$Y$6,'Normative data'!$Z$3:$AG$6,,-1),'Normative data'!$Z$2:$AG$2,"Not Found",-1))} -> Poor | CS7: 3 | CT7: 6 | CU7: {=_xlfn.XLOOKUP(CS7&CT7,(VLOOKUP!$A$3:$A$250)&(VLOOKUP!$B$3:$B$250),VLOOKUP!$C$3:$C$250,"Incomplete",-1)} -> 420 | CV7: {=_xlfn.XLOOKUP(CU7, _xlfn.XLOOKUP(E7, 'Normative data'!$Y$11:$Y$14, 'Normative data'!$Z$11:$AG$14, ,-1), 'Normative data'!$Z$10:$AG$10, "Not Found", -1)} -> Poor | CW7: {=IF(OR(ISBLANK(CS7),ISBLANK(CT7)),"Incomplete",_xlfn.XLOOKUP(CS7&CT7,VLOOKUP!$A$4:$A$250&VLOOKUP!$B$4:$B$250,VLOOKUP!$D$4:$D$250,"0"))} -> 25
A8: Turner | B8: Abigail | C8: Female | F8: 8E | G8: 2026 | I8: 2 | J8: Netball | K8: U/14 C | S8: 83.8 | T8: 163.4 | AY8: =IF(OR(ISBLANK(U8), ISBLANK(AQ8)), "Incomplete", (60.7*AQ8)+(45.3*U8)-2055) -> Incomplete | BA8: =IF(OR(ISBLANK(U8), ISBLANK(AS8)), "Incomplete", (60.7*AS8)+(45.3*U8)-2055) -> Incomplete | BC8: =IF(OR(ISBLANK(U8), ISBLANK(AU8)), "Incomplete", (60.7*AU8)+(45.3*U8)-2055) -> Incomplete | BE8: =IF(OR(ISBLANK(U8), ISBLANK(AW8)), "Incomplete", (60.7*AW8)+(45.3*U8)-2055) -> Incomplete | BH8: 13 | BI8: =IF(OR(ISBLANK(BG8), ISBLANK(BH8)),"Incomplete",(SUM(BH8-BG8))) -> Incomplete | BK8: 13 | BM8: 11.5 | BW8: =IFERROR(SUM(BQ8+BR8+BS8)/(3*(T8-S8))*100, "Incomplete") -> 0 | BX8: =_xlfn.XLOOKUP(BW8,'Normative data'!$V$3:$V$6,'Normative data'!$W$3:$W$6,"Not Found",-1) -> Not completed | BY8: =IFERROR(SUM(BT8+BU8+BV8)/(3*(T8-S8))*100, "Incomplete") -> 0 | BZ8: =_xlfn.XLOOKUP(BY8,'Normative data'!$V$3:$V$6,'Normative data'!$W$3:$W$6,"Not Found",-1) -> Not completed | CG8: 21 | CH8: =_xlfn.XLOOKUP(CG8, 'Normative data'!$S$9:$S$15,'Normative data'!$T$9:$T$15, "Not Found", -1) -> Average | CI8: 22.81 | CJ8: =_xlfn.XLOOKUP(CI8, 'Normative data'!$S$9:$S$15, 'Normative data'!$T$9:$T$15, "Not Found", -1) -> Below Average | CK8: 2.3 | CL8: 4.35 | CN8: 7.38 | CO8: 6.78 | CQ8: 5.3 | CR8: {=IF(OR(ISBLANK(E8),ISBLANK(CQ8)),"Incomplete",_xlfn.XLOOKUP(CQ8,_xlfn.XLOOKUP(E8,'Normative data'!$Y$3:$Y$6,'Normative data'!$Z$3:$AG$6,,-1),'Normative data'!$Z$2:$AG$2,"Not Found",-1))} -> Incomplete | CS8: 5 | CT8: 3 | CU8: {=_xlfn.XLOOKUP(CS8&CT8,(VLOOKUP!$A$3:$A$250)&(VLOOKUP!$B$3:$B$250),VLOOKUP!$C$3:$C$250,"Incomplete",-1)} -> 700 | CV8: {=_xlfn.XLOOKUP(CU8, _xlfn.XLOOKUP(E8, 'Normative data'!$Y$11:$Y$14, 'Normative data'!$Z$11:$AG$14, ,-1), 'Normative data'!$Z$10:$AG$10, "Not Found", -1)} -> Poor | CW8: {=IF(OR(ISBLANK(CS8),ISBLANK(CT8)),"Incomplete",_xlfn.XLOOKUP(CS8&CT8,VLOOKUP!$A$4:$A$250&VLOOKUP!$B$4:$B$250,VLOOKUP!$D$4:$D$250,"0"))} -> 31
A9: van Sittert | B9: Abigail | C9: Female | D9: 40036 | E9: 16.6 | F9: 11P | G9: 2026 | I9: 2 | J9: Netball | K9: U/17 A | S9: 89.4 | T9: 173.9 | U9: 56.5 | V9: 32.1 | W9: 12.6 | X9: 43.9 | Y9: 23.8 | Z9: 18.7 | AA9: 22.3 | AB9: 7.45 | AC9: 114.1 | AD9: 7.42 | AE9: 113.7 | AF9: 2.2 | AG9: 78.3 | AH9: 2.2 | AI9: 78.2 | AJ9: 308.2 | AK9: 310.3 | AL9: 279.6 | AM9: 281.7 | AN9: 103 | AO9: 0.81 | AP9: 6.2 | AQ9: 22.5 | AR9: 0.428 | AS9: 24.9 | AT9: 0.451 | AU9: 14.3 | AV9: 0.342 | AW9: 16.4 | AX9: 0.366 | AY9: =IF(OR(ISBLANK(U9), ISBLANK(AQ9)), "Incomplete", (60.7*AQ9)+(45.3*U9)-2055) -> 1870.2 | BA9: =IF(OR(ISBLANK(U9), ISBLANK(AS9)), "Incomplete", (60.7*AS9)+(45.3*U9)-2055) -> 2015.88 | BC9: =IF(OR(ISBLANK(U9), ISBLANK(AU9)), "Incomplete", (60.7*AU9)+(45.3*U9)-2055) -> 1372.46 | BE9: =IF(OR(ISBLANK(U9), ISBLANK(AW9)), "Incomplete", (60.7*AW9)+(45.3*U9)-2055) -> 1499.93 | BG9: 7.5 | BH9: 40.9 | BI9: =IF(OR(ISBLANK(BG9), ISBLANK(BH9)),"Incomplete",(SUM(BH9-BG9))) -> 33.4 | BK9: 9.5 | BM9: 11.5 | BO9: 39.5 | BP9: 40.8 | BQ9: 87 | BR9: 78 | BS9: 67 | BT9: 86 | BU9: 76 | BV9: 74 | BW9: =IFERROR(SUM(BQ9+BR9+BS9)/(3*(T9-S9))*100, "Incomplete") -> 91.518738 | BX9: =_xlfn.XLOOKUP(BW9,'Normative data'!$V$3:$V$6,'Normative data'!$W$3:$W$6,"Not Found",-1) -> High risk | BY9: =IFERROR(SUM(BT9+BU9+BV9)/(3*(T9-S9))*100, "Incomplete") -> 93.096647 | BZ9: =_xlfn.XLOOKUP(BY9,'Normative data'!$V$3:$V$6,'Normative data'!$W$3:$W$6,"Not Found",-1) -> High risk | CA9: 19 | CE9: 7 | CG9: 19.56 | CH9: =_xlfn.XLOOKUP(CG9, 'Normative data'!$S$9:$S$15,'Normative data'!$T$9:$T$15, "Not Found", -1) -> Average | CI9: 19.68 | CJ9: =_xlfn.XLOOKUP(CI9, 'Normative data'!$S$9:$S$15, 'Normative data'!$T$9:$T$15, "Not Found", -1) -> Average | CQ9: 4.4 | CR9: {=IF(OR(ISBLANK(E9),ISBLANK(CQ9)),"Incomplete",_xlfn.XLOOKUP(CQ9,_xlfn.XLOOKUP(E9,'Normative data'!$Y$3:$Y$6,'Normative data'!$Z$3:$AG$6,,-1),'Normative data'!$Z$2:$AG$2,"Not Found",-1))} -> Poor | CS9: 4 | CT9: 4 | CU9: {=_xlfn.XLOOKUP(CS9&CT9,(VLOOKUP!$A$3:$A$250)&(VLOOKUP!$B$3:$B$250),VLOOKUP!$C$3:$C$250,"Incomplete",-1)} -> 540 | CV9: {=_xlfn.XLOOKUP(CU9, _xlfn.XLOOKUP(E9, 'Normative data'!$Y$11:$Y$14, 'Normative data'!$Z$11:$AG$14, ,-1), 'Normative data'!$Z$10:$AG$10, "Not Found", -1)} -> Poor | CW9: {=IF(OR(ISBLANK(CS9),ISBLANK(CT9)),"Incomplete",_xlfn.XLOOKUP(CS9&CT9,VLOOKUP!$A$4:$A$250&VLOOKUP!$B$4:$B$250,VLOOKUP!$D$4:$D$250,"0"))} -> 28
A10: Eve | B10: Abrahams | C10: Female | D10: 39725 | E10: 15 | F10: 11 | G10: 2025 | H10: January | I10: 1 | AY10: =IF(OR(ISBLANK(U10), ISBLANK(AQ10)), "Incomplete", (60.7*AQ10)+(45.3*U10)-2055) -> Incomplete | BA10: =IF(OR(ISBLANK(U10), ISBLANK(AS10)), "Incomplete", (60.7*AS10)+(45.3*U10)-2055) -> Incomplete | BC10: =IF(OR(ISBLANK(U10), ISBLANK(AU10)), "Incomplete", (60.7*AU10)+(45.3*U10)-2055) -> Incomplete | BE10: =IF(OR(ISBLANK(U10), ISBLANK(AW10)), "Incomplete", (60.7*AW10)+(45.3*U10)-2055) -> Incomplete | BG10: 21.5 | BH10: 41 | BI10: =IF(OR(ISBLANK(BG10), ISBLANK(BH10)),"Incomplete",(SUM(BH10-BG10))) -> 19.5 | BW10: =IFERROR(SUM(BQ10+BR10+BS10)/(3*(T10-S10))*100, "Incomplete") -> Incomplete | BX10: =_xlfn.XLOOKUP(BW10,'Normative data'!$V$3:$V$6,'Normative data'!$W$3:$W$6,"Not Found",-1) -> Very low risk | BY10: =IFERROR(SUM(BT10+BU10+BV10)/(3*(T10-S10))*100, "Incomplete") -> Incomplete | BZ10: =_xlfn.XLOOKUP(BY10,'Normative data'!$V$3:$V$6,'Normative data'!$W$3:$W$6,"Not Found",-1) -> Very low risk | CE10: 30 | CH10: =_xlfn.XLOOKUP(CG10, 'Normative data'!$S$9:$S$15,'Normative data'!$T$9:$T$15, "Not Found", -1) -> not completed | CJ10: =_xlfn.XLOOKUP(CI10, 'Normative data'!$S$9:$S$15, 'Normative data'!$T$9:$T$15, "Not Found", -1) -> not completed | CK10: 1.94 | CL10: 5.15 | CN10: 5.74 | CO10: 8.71 | CQ10: 10.1 | CR10: {=IF(OR(ISBLANK(E10),ISBLANK(CQ10)),"Incomplete",_xlfn.XLOOKUP(CQ10,_xlfn.XLOOKUP(E10,'Normative data'!$Y$3:$Y$6,'Normative data'!$Z$3:$AG$6,,-1),'Normative data'!$Z$2:$AG$2,"Not Found",-1))} -> Very good | CS10: 10 | CT10: 1 | CU10: {=_xlfn.XLOOKUP(CS10&CT10,(VLOOKUP!$A$3:$A$250)&(VLOOKUP!$B$3:$B$250),VLOOKUP!$C$3:$C$250,"Incomplete",-1)} -> 1680 | CV10: {=_xlfn.XLOOKUP(CU10, _xlfn.XLOOKUP(E10, 'Normative data'!$Y$11:$Y$14, 'Normative data'!$Z$11:$AG$14, ,-1), 'Normative data'!$Z$10:$AG$10, "Not Found", -1)} -> Good | CW10: {=IF(OR(ISBLANK(CS10),ISBLANK(CT10)),"Incomplete",_xlfn.XLOOKUP(CS10&CT10,VLOOKUP!$A$4:$A$250&VLOOKUP!$B$4:$B$250,VLOOKUP!$D$4:$D$250,"0"))} -> 47
A11: Zaynab | B11: Abrahams | C11: Female | F11: 10 | G11: 2025 | H11: January | I11: 1 | AY11: =IF(OR(ISBLANK(U11), ISBLANK(AQ11)), "Incomplete", (60.7*AQ11)+(45.3*U11)-2055) -> Incomplete | BA11: =IF(OR(ISBLANK(U11), ISBLANK(AS11)), "Incomplete", (60.7*AS11)+(45.3*U11)-2055) -> Incomplete | BC11: =IF(OR(ISBLANK(U11), ISBLANK(AU11)), "Incomplete", (60.7*AU11)+(45.3*U11)-2055) -> Incomplete | BE11: =IF(OR(ISBLANK(U11), ISBLANK(AW11)), "Incomplete", (60.7*AW11)+(45.3*U11)-2055) -> Incomplete | BG11: 17 | BH11: 36.5 | BI11: =IF(OR(ISBLANK(BG11), ISBLANK(BH11)),"Incomplete",(SUM(BH11-BG11))) -> 19.5 | BK11: 3 | BM11: 3 | BW11: =IFERROR(SUM(BQ11+BR11+BS11)/(3*(T11-S11))*100, "Incomplete") -> Incomplete | BX11: =_xlfn.XLOOKUP(BW11,'Normative data'!$V$3:$V$6,'Normative data'!$W$3:$W$6,"Not Found",-1) -> Very low risk | BY11: =IFERROR(SUM(BT11+BU11+BV11)/(3*(T11-S11))*100, "Incomplete") -> Incomplete | BZ11: =_xlfn.XLOOKUP(BY11,'Normative data'!$V$3:$V$6,'Normative data'!$W$3:$W$6,"Not Found",-1) -> Very low risk | CE11: 2 | CH11: =_xlfn.XLOOKUP(CG11, 'Normative data'!$S$9:$S$15,'Normative data'!$T$9:$T$15, "Not Found", -1) -> not completed | CJ11: =_xlfn.XLOOKUP(CI11, 'Normative data'!$S$9:$S$15, 'Normative data'!$T$9:$T$15, "Not Found", -1) -> not completed | CK11: 2.35 | CL11: 4.26 | CN11: 7.54 | CO11: 6.63 | CR11: {=IF(OR(ISBLANK(E11),ISBLANK(CQ11)),"Incomplete",_xlfn.XLOOKUP(CQ11,_xlfn.XLOOKUP(E11,'Normative data'!$Y$3:$Y$6,'Normative data'!$Z$3:$AG$6,,-1),'Normative data'!$Z$2:$AG$2,"Not Found",-1))} -> Incomplete | CU11: {=_xlfn.XLOOKUP(CS11&CT11,(VLOOKUP!$A$3:$A$250)&(VLOOKUP!$B$3:$B$250),VLOOKUP!$C$3:$C$250,"Incomplete",-1)} -> Incomplete | CV11: {=_xlfn.XLOOKUP(CU11, _xlfn.XLOOKUP(E11, 'Normative data'!$Y$11:$Y$14, 'Normative data'!$Z$11:$AG$14, ,-1), 'Normative data'!$Z$10:$AG$10, "Not Found", -1)} -> Excellent | CW11: {=IF(OR(ISBLANK(CS11),ISBLANK(CT11)),"Incomplete",_xlfn.XLOOKUP(CS11&CT11,VLOOKUP!$A$4:$A$250&VLOOKUP!$B$4:$B$250,VLOOKUP!$D$4:$D$250,"0"))} -> Incomplete
A12: Amy | B12: Adams | C12: Female | D12: 40424 | F12: 9 | G12: 2025 | H12: January | I12: 1 | J12: Hockey | T12: 157 | U12: 59.8 | W12: 20.6 | X12: =SUM(T12-W12) -> 136.4 | Y12: 21.4 | Z12: 24.3 | AA12: 34.4 | AY12: =IF(OR(ISBLANK(U12), ISBLANK(AQ12)), "Incomplete", (60.7*AQ12)+(45.3*U12)-2055) -> Incomplete | BA12: =IF(OR(ISBLANK(U12), ISBLANK(AS12)), "Incomplete", (60.7*AS12)+(45.3*U12)-2055) -> Incomplete | BC12: =IF(OR(ISBLANK(U12), ISBLANK(AU12)), "Incomplete", (60.7*AU12)+(45.3*U12)-2055) -> Incomplete | BE12: =IF(OR(ISBLANK(U12), ISBLANK(AW12)), "Incomplete", (60.7*AW12)+(45.3*U12)-2055) -> Incomplete | BI12: =IF(OR(ISBLANK(BG12), ISBLANK(BH12)),"Incomplete",(SUM(BH12-BG12))) -> Incomplete | BK12: 8 | BM12: 7 | BW12: =IFERROR(SUM(BQ12+BR12+BS12)/(3*(T12-S12))*100, "Incomplete") -> 0 | BX12: =_xlfn.XLOOKUP(BW12,'Normative data'!$V$3:$V$6,'Normative data'!$W$3:$W$6,"Not Found",-1) -> Not completed | BY12: =IFERROR(SUM(BT12+BU12+BV12)/(3*(T12-S12))*100, "Incomplete") -> 0 | BZ12: =_xlfn.XLOOKUP(BY12,'Normative data'!$V$3:$V$6,'Normative data'!$W$3:$W$6,"Not Found",-1) -> Not completed | CG12: 17.23 | CH12: =_xlfn.XLOOKUP(CG12, 'Normative data'!$S$9:$S$15,'Normative data'!$T$9:$T$15, "Not Found", -1) -> Above Average | CI12: 17.34 | CJ12: =_xlfn.XLOOKUP(CI12, 'Normative data'!$S$9:$S$15, 'Normative data'!$T$9:$T$15, "Not Found", -1) -> Above Average | CK12: 2.19 | CL12: 4.57 | CN12: 6.47 | CO12: 7.73 | CR12: {=IF(OR(ISBLANK(E12),ISBLANK(CQ12)),"Incomplete",_xlfn.XLOOKUP(CQ12,_xlfn.XLOOKUP(E12,'Normative data'!$Y$3:$Y$6,'Normative data'!$Z$3:$AG$6,,-1),'Normative data'!$Z$2:$AG$2,"Not Found",-1))} -> Incomplete | CU12: {=_xlfn.XLOOKUP(CS12&CT12,(VLOOKUP!$A$3:$A$250)&(VLOOKUP!$B$3:$B$250),VLOOKUP!$C$3:$C$250,"Incomplete",-1)} -> Incomplete | CV12: {=_xlfn.XLOOKUP(CU12, _xlfn.XLOOKUP(E12, 'Normative data'!$Y$11:$Y$14, 'Normative data'!$Z$11:$AG$14, ,-1), 'Normative data'!$Z$10:$AG$10, "Not Found", -1)} -> Excellent | CW12: {=IF(OR(ISBLANK(CS12),ISBLANK(CT12)),"Incomplete",_xlfn.XLOOKUP(CS12&CT12,VLOOKUP!$A$4:$A$250&VLOOKUP!$B$4:$B$250,VLOOKUP!$D$4:$D$250,"0"))} -> Incomplete
A13: Amy | B13: Adams | C13: Female | D13: 40424 | F13: 9 | G13: 2025 | H13: January | I13: 1 | J13: Hockey | AY13: =IF(OR(ISBLANK(U13), ISBLANK(AQ13)), "Incomplete", (60.7*AQ13)+(45.3*U13)-2055) -> Incomplete | BA13: =IF(OR(ISBLANK(U13), ISBLANK(AS13)), "Incomplete", (60.7*AS13)+(45.3*U13)-2055) -> Incomplete | BC13: =IF(OR(ISBLANK(U13), ISBLANK(AU13)), "Incomplete", (60.7*AU13)+(45.3*U13)-2055) -> Incomplete | BE13: =IF(OR(ISBLANK(U13), ISBLANK(AW13)), "Incomplete", (60.7*AW13)+(45.3*U13)-2055) -> Incomplete | BG13: 14.5 | BH13: 27 | BI13: =IF(OR(ISBLANK(BG13), ISBLANK(BH13)),"Incomplete",(SUM(BH13-BG13))) -> 12.5 | BK13: 7 | BM13: 7 | BW13: =IFERROR(SUM(BQ13+BR13+BS13)/(3*(T13-S13))*100, "Incomplete") -> Incomplete | BX13: =_xlfn.XLOOKUP(BW13,'Normative data'!$V$3:$V$6,'Normative data'!$W$3:$W$6,"Not Found",-1) -> Very low risk | BY13: =IFERROR(SUM(BT13+BU13+BV13)/(3*(T13-S13))*100, "Incomplete") -> Incomplete | BZ13: =_xlfn.XLOOKUP(BY13,'Normative data'!$V$3:$V$6,'Normative data'!$W$3:$W$6,"Not Found",-1) -> Very low risk | CE13: 10 | CG13: 17.45 | CH13: =_xlfn.XLOOKUP(CG13, 'Normative data'!$S$9:$S$15,'Normative data'!$T$9:$T$15, "Not Found", -1) -> Above Average | CI13: 16.93 | CJ13: =_xlfn.XLOOKUP(CI13, 'Normative data'!$S$9:$S$15, 'Normative data'!$T$9:$T$15, "Not Found", -1) -> Above Average | CR13: {=IF(OR(ISBLANK(E13),ISBLANK(CQ13)),"Incomplete",_xlfn.XLOOKUP(CQ13,_xlfn.XLOOKUP(E13,'Normative data'!$Y$3:$Y$6,'Normative data'!$Z$3:$AG$6,,-1),'Normative data'!$Z$2:$AG$2,"Not Found",-1))} -> Incomplete | CU13: {=_xlfn.XLOOKUP(CS13&CT13,(VLOOKUP!$A$3:$A$250)&(VLOOKUP!$B$3:$B$250),VLOOKUP!$C$3:$C$250,"Incomplete",-1)} -> Incomplete | CV13: {=_xlfn.XLOOKUP(CU13, _xlfn.XLOOKUP(E13, 'Normative data'!$Y$11:$Y$14, 'Normative data'!$Z$11:$AG$14, ,-1), 'Normative data'!$Z$10:$AG$10, "Not Found", -1)} -> Excellent | CW13: {=IF(OR(ISBLANK(CS13),ISBLANK(CT13)),"Incomplete",_xlfn.XLOOKUP(CS13&CT13,VLOOKUP!$A$4:$A$250&VLOOKUP!$B$4:$B$250,VLOOKUP!$D$4:$D$250,"0"))} -> Incomplete
A14: Amy | B14: Adams | C14: Female | D14: 40424 | F14: 9 | G14: 2025 | H14: August | I14: 3 | J14: Hockey | T14: 158.8 | U14: 61.9 | AQ14: 13.1 | AR14: 0.327 | AS14: 18.2 | AT14: 0.385 | AU14: 13.3 | AV14: 0.329 | AW14: 8.8 | AX14: 0.268 | AY14: =IF(OR(ISBLANK(U14), ISBLANK(#REF!)), "Incomplete", (60.7*#REF!)+(45.3*U14)-2055) -> #REF! | BA14: =IF(OR(ISBLANK(U14), ISBLANK(#REF!)), "Incomplete", (60.7*#REF!)+(45.3*U14)-2055) -> #REF! | BC14: =IF(OR(ISBLANK(U14), ISBLANK(#REF!)), "Incomplete", (60.7*#REF!)+(45.3*U14)-2055) -> #REF! | BE14: =IF(OR(ISBLANK(U14), ISBLANK(#REF!)), "Incomplete", (60.7*#REF!)+(45.3*U14)-2055) -> #REF! | BI14: =IF(OR(ISBLANK(BG14), ISBLANK(BH14)),"Incomplete",(SUM(BH14-BG14))) -> Incomplete | BW14: =IFERROR(SUM(BQ14+BR14+BS14)/(3*(T14-S14))*100, "Incomplete") -> Incomplete | BX14: =_xlfn.XLOOKUP(BW14,'Normative data'!$V$3:$V$6,'Normative data'!$W$3:$W$6,"Not Found",-1) -> Very low risk | BY14: =IFERROR(SUM(BT14+BU14+BV14)/(3*(T14-S14))*100, "Incomplete") -> Incomplete | BZ14: =_xlfn.XLOOKUP(BY14,'Normative data'!$V$3:$V$6,'Normative data'!$W$3:$W$6,"Not Found",-1) -> Very low risk | CG14: 17.92 | CH14: =_xlfn.XLOOKUP(CG14, 'Normative data'!$S$9:$S$15,'Normative data'!$T$9:$T$15, "Not Found", -1) -> Above Average | CI14: 18.16 | CJ14: =_xlfn.XLOOKUP(CI14, 'Normative data'!$S$9:$S$15, 'Normative data'!$T$9:$T$15, "Not Found", -1) -> Average | CK14: 2.21 | CL14: 4.52 | CN14: 6.53 | CO14: 7.66 | CR14: {=IF(OR(ISBLANK(E14),ISBLANK(CQ14)),"Incomplete",_xlfn.XLOOKUP(CQ14,_xlfn.XLOOKUP(E14,'Normative data'!$Y$3:$Y$6,'Normative data'!$Z$3:$AG$6,,-1),'Normative data'!$Z$2:$AG$2,"Not Found",-1))} -> Incomplete | CU14: {=_xlfn.XLOOKUP(CS14&CT14,(VLOOKUP!$A$3:$A$250)&(VLOOKUP!$B$3:$B$250),VLOOKUP!$C$3:$C$250,"Incomplete",-1)} -> Incomplete | CV14: {=_xlfn.XLOOKUP(CU14, _xlfn.XLOOKUP(E14, 'Normative data'!$Y$11:$Y$14, 'Normative data'!$Z$11:$AG$14, ,-1), 'Normative data'!$Z$10:$AG$10, "Not Found", -1)} -> Excellent | CW14: {=IF(OR(ISBLANK(CS14),ISBLANK(CT14)),"Incomplete",_xlfn.XLOOKUP(CS14&CT14,VLOOKUP!$A$4:$A$250&VLOOKUP!$B$4:$B$250,VLOOKUP!$D$4:$D$250,"0"))} -> Incomplete
A15: Amy | B15: Adams | C15: Female | D15: 40424 | G15: 2026 | H15: January | I15: 1 | AQ15: 8.7 | AR15: 0.266 | AS15: 14.9 | AT15: 0.349 | AU15: 10.8 | AV15: 0.297 | AW15: 11.9 | AX15: 0.312 | AY15: =IF(OR(ISBLANK(U15), ISBLANK(AQ15)), "Incomplete", (60.7*AQ15)+(45.3*U15)-2055) -> Incomplete | BA15: =IF(OR(ISBLANK(U15), ISBLANK(AS15)), "Incomplete", (60.7*AS15)+(45.3*U15)-2055) -> Incomplete | BC15: =IF(OR(ISBLANK(U15), ISBLANK(AU15)), "Incomplete", (60.7*AU15)+(45.3*U15)-2055) -> Incomplete | BE15: =IF(OR(ISBLANK(U15), ISBLANK(AW15)), "Incomplete", (60.7*AW15)+(45.3*U15)-2055) -> Incomplete | BG15: 18.5 | BH15: 38 | BI15: =IF(OR(ISBLANK(BG15), ISBLANK(BH15)),"Incomplete",(SUM(BH15-BG15))) -> 19.5 | BW15: =IFERROR(SUM(BQ15+BR15+BS15)/(3*(T15-S15))*100, "Incomplete") -> Incomplete | BX15: =_xlfn.XLOOKUP(BW15,'Normative data'!$V$3:$V$6,'Normative data'!$W$3:$W$6,"Not Found",-1) -> Very low risk | BY15: =IFERROR(SUM(BT15+BU15+BV15)/(3*(T15-S15))*100, "Incomplete") -> Incomplete | BZ15: =_xlfn.XLOOKUP(BY15,'Normative data'!$V$3:$V$6,'Normative data'!$W$3:$W$6,"Not Found",-1) -> Very low risk | CG15: 18.74 | CH15: =_xlfn.XLOOKUP(CG15, 'Normative data'!$S$9:$S$15,'Normative data'!$T$9:$T$15, "Not Found", -1) -> Average | CI15: 19 | CJ15: =_xlfn.XLOOKUP(CI15, 'Normative data'!$S$9:$S$15, 'Normative data'!$T$9:$T$15, "Not Found", -1) -> Average | CK15: 2.08 | CL15: 4.81 | CN15: 6.64 | CO15: 7.53 | CQ15: 9.1 | CR15: {=IF(OR(ISBLANK(E15),ISBLANK(CQ15)),"Incomplete",_xlfn.XLOOKUP(CQ15,_xlfn.XLOOKUP(E15,'Normative data'!$Y$3:$Y$6,'Normative data'!$Z$3:$AG$6,,-1),'Normative data'!$Z$2:$AG$2,"Not Found",-1))} -> Incomplete | CS15: 9 | CT15: 1 | CU15: {=_xlfn.XLOOKUP(CS15&CT15,(VLOOKUP!$A$3:$A$250)&(VLOOKUP!$B$3:$B$250),VLOOKUP!$C$3:$C$250,"Incomplete",-1)} -> 1460 | CV15: {=_xlfn.XLOOKUP(CU15, _xlfn.XLOOKUP(E15, 'Normative data'!$Y$11:$Y$14, 'Normative data'!$Z$11:$AG$14, ,-1), 'Normative data'!$Z$10:$AG$10, "Not Found", -1)} -> Average | CW15: {=IF(OR(ISBLANK(CS15),ISBLANK(CT15)),"Incomplete",_xlfn.XLOOKUP(CS15&CT15,VLOOKUP!$A$4:$A$250&VLOOKUP!$B$4:$B$250,VLOOKUP!$D$4:$D$250,"0"))} -> 44
A16: Liqhamile | B16: Adonis | C16: Female | D16: 39844 | F16: 10 | G16: 2025 | H16: August | I16: 3 | AY16: =IF(OR(ISBLANK(U16), ISBLANK(AQ16)), "Incomplete", (60.7*AQ16)+(45.3*U16)-2055) -> Incomplete | BA16: =IF(OR(ISBLANK(U16), ISBLANK(AS16)), "Incomplete", (60.7*AS16)+(45.3*U16)-2055) -> Incomplete | BC16: =IF(OR(ISBLANK(U16), ISBLANK(AU16)), "Incomplete", (60.7*AU16)+(45.3*U16)-2055) -> Incomplete | BE16: =IF(OR(ISBLANK(U16), ISBLANK(AW16)), "Incomplete", (60.7*AW16)+(45.3*U16)-2055) -> Incomplete | BI16: =IF(OR(ISBLANK(BG16), ISBLANK(BH16)),"Incomplete",(SUM(BH16-BG16))) -> Incomplete | BW16: =IFERROR(SUM(BQ16+BR16+BS16)/(3*(T16-S16))*100, "Incomplete") -> Incomplete | BX16: =_xlfn.XLOOKUP(BW16,'Normative data'!$V$3:$V$6,'Normative data'!$W$3:$W$6,"Not Found",-1) -> Very low risk | BY16: =IFERROR(SUM(BT16+BU16+BV16)/(3*(T16-S16))*100, "Incomplete") -> Incomplete | BZ16: =_xlfn.XLOOKUP(BY16,'Normative data'!$V$3:$V$6,'Normative data'!$W$3:$W$6,"Not Found",-1) -> Very low risk | CH16: =_xlfn.XLOOKUP(CG16, 'Normative data'!$S$9:$S$15,'Normative data'!$T$9:$T$15, "Not Found", -1) -> not completed | CJ16: =_xlfn.XLOOKUP(CI16, 'Normative data'!$S$9:$S$15, 'Normative data'!$T$9:$T$15, "Not Found", -1) -> not completed | CK16: 2.19 | CL16: 4.57 | CN16: 6.99 | CO16: 7.15 | CR16: {=IF(OR(ISBLANK(E16),ISBLANK(CQ16)),"Incomplete",_xlfn.XLOOKUP(CQ16,_xlfn.XLOOKUP(E16,'Normative data'!$Y$3:$Y$6,'Normative data'!$Z$3:$AG$6,,-1),'Normative data'!$Z$2:$AG$2,"Not Found",-1))} -> Incomplete | CU16: {=_xlfn.XLOOKUP(CS16&CT16,(VLOOKUP!$A$3:$A$250)&(VLOOKUP!$B$3:$B$250),VLOOKUP!$C$3:$C$250,"Incomplete",-1)} -> Incomplete | CV16: {=_xlfn.XLOOKUP(CU16, _xlfn.XLOOKUP(E16, 'Normative data'!$Y$11:$Y$14, 'Normative data'!$Z$11:$AG$14, ,-1), 'Normative data'!$Z$10:$AG$10, "Not Found", -1)} -> Excellent | CW16: {=IF(OR(ISBLANK(CS16),ISBLANK(CT16)),"Incomplete",_xlfn.XLOOKUP(CS16&CT16,VLOOKUP!$A$4:$A$250&VLOOKUP!$B$4:$B$250,VLOOKUP!$D$4:$D$250,"0"))} -> Incomplete
A17: Liqhamile | B17: Adonis | C17: Female | D17: 39844 | G17: 2026 | H17: January | I17: 1 | AQ17: 18.5 | AR17: 0.388 | AS17: 18.4 | AT17: 0.387 | AU17: 10 | AV17: 0.286 | AW17: 10.1 | AX17: 0.287 | AY17: =IF(OR(ISBLANK(U17), ISBLANK(AQ17)), "Incomplete", (60.7*AQ17)+(45.3*U17)-2055) -> Incomplete | BA17: =IF(OR(ISBLANK(U17), ISBLANK(AS17)), "Incomplete", (60.7*AS17)+(45.3*U17)-2055) -> Incomplete | BC17: =IF(OR(ISBLANK(U17), ISBLANK(AU17)), "Incomplete", (60.7*AU17)+(45.3*U17)-2055) -> Incomplete | BE17: =IF(OR(ISBLANK(U17), ISBLANK(AW17)), "Incomplete", (60.7*AW17)+(45.3*U17)-2055) -> Incomplete | BG17: 15 | BH17: 64 | BI17: =IF(OR(ISBLANK(BG17), ISBLANK(BH17)),"Incomplete",(SUM(BH17-BG17))) -> 49 | BW17: =IFERROR(SUM(BQ17+BR17+BS17)/(3*(T17-S17))*100, "Incomplete") -> Incomplete | BX17: =_xlfn.XLOOKUP(BW17,'Normative data'!$V$3:$V$6,'Normative data'!$W$3:$W$6,"Not Found",-1) -> Very low risk | BY17: =IFERROR(SUM(BT17+BU17+BV17)/(3*(T17-S17))*100, "Incomplete") -> Incomplete | BZ17: =_xlfn.XLOOKUP(BY17,'Normative data'!$V$3:$V$6,'Normative data'!$W$3:$W$6,"Not Found",-1) -> Very low risk | CC17: 37 | CE17: 2 | CH17: =_xlfn.XLOOKUP(CG17, 'Normative data'!$S$9:$S$15,'Normative data'!$T$9:$T$15, "Not Found", -1) -> not completed | CJ17: =_xlfn.XLOOKUP(CI17, 'Normative data'!$S$9:$S$15, 'Normative data'!$T$9:$T$15, "Not Found", -1) -> not completed | CK17: 2.12 | CL17: 4.72 | CN17: 7.34 | CO17: 6.81 | CQ17: 3.6 | CR17: {=IF(OR(ISBLANK(E17),ISBLANK(CQ17)),"Incomplete",_xlfn.XLOOKUP(CQ17,_xlfn.XLOOKUP(E17,'Normative data'!$Y$3:$Y$6,'Normative data'!$Z$3:$AG$6,,-1),'Normative data'!$Z$2:$AG$2,"Not Found",-1))} -> Incomplete | CS17: 3 | CT17: 6 | CU17: {=_xlfn.XLOOKUP(CS17&CT17,(VLOOKUP!$A$3:$A$250)&(VLOOKUP!$B$3:$B$250),VLOOKUP!$C$3:$C$250,"Incomplete",-1)} -> 420 | CV17: {=_xlfn.XLOOKUP(CU17, _xlfn.XLOOKUP(E17, 'Normative data'!$Y$11:$Y$14, 'Normative data'!$Z$11:$AG$14, ,-1), 'Normative data'!$Z$10:$AG$10, "Not Found", -1)} -> Very poor | CW17: {=IF(OR(ISBLANK(CS17),ISBLANK(CT17)),"Incomplete",_xlfn.XLOOKUP(CS17&CT17,VLOOKUP!$A$4:$A$250&VLOOKUP!$B$4:$B$250,VLOOKUP!$D$4:$D$250,"0"))} -> 25
A18: Liqhumile | B18: Adonis | C18: Female | D18: 39844 | F18: 10 | G18: 2025 | H18: August | I18: 3 | J18: Netball | T18: 166.4 | U18: 75.9 | W18: 27 | X18: =SUM(T18-W18) -> 139.4 | Y18: 27.3 | Z18: 27.4 | AA18: 35.9 | AQ18: 25.6 | AR18: 0.414 | AS18: 30.9 | AT18: 0.351 | AU18: 13.3 | AV18: 0.329 | AW18: 11.7 | AX18: 0.309 | AY18: =IF(OR(ISBLANK(U18), ISBLANK(AQ18)), "Incomplete", (60.7*AQ18)+(45.3*U18)-2055) -> 2937.19 | BA18: =IF(OR(ISBLANK(U18), ISBLANK(AS18)), "Incomplete", (60.7*AS18)+(45.3*U18)-2055) -> 3258.9 | BC18: =IF(OR(ISBLANK(U18), ISBLANK(AU18)), "Incomplete", (60.7*AU18)+(45.3*U18)-2055) -> 2190.58 | BE18: =IF(OR(ISBLANK(U18), ISBLANK(AW18)), "Incomplete", (60.7*AW18)+(45.3*U18)-2055) -> 2093.46 | BG18: 17 | BH18: 50 | BI18: =IF(OR(ISBLANK(#REF!), ISBLANK(#REF!)),"Incomplete",(SUM(#REF!-#REF!))) -> #REF! | BK18: 5 | BM18: 5 | BW18: =IFERROR(SUM(BQ18+BR18+BS18)/(3*(T18-S18))*100, "Incomplete") -> 0 | BX18: =_xlfn.XLOOKUP(BW18,'Normative data'!$V$3:$V$6,'Normative data'!$W$3:$W$6,"Not Found",-1) -> Not completed | BY18: =IFERROR(SUM(BT18+BU18+BV18)/(3*(T18-S18))*100, "Incomplete") -> 0 | BZ18: =_xlfn.XLOOKUP(BY18,'Normative data'!$V$3:$V$6,'Normative data'!$W$3:$W$6,"Not Found",-1) -> Not completed | CE18: 1 | CH18: =_xlfn.XLOOKUP(CG18, 'Normative data'!$S$9:$S$15,'Normative data'!$T$9:$T$15, "Not Found", -1) -> not completed | CJ18: =_xlfn.XLOOKUP(CI18, 'Normative data'!$S$9:$S$15, 'Normative data'!$T$9:$T$15, "Not Found", -1) -> not completed | CK18: 2.29 | CL18: 4.37 | CN18: 7.46 | CO18: 7.7 | CR18: {=IF(OR(ISBLANK(E18),ISBLANK(CQ18)),"Incomplete",_xlfn.XLOOKUP(CQ18,_xlfn.XLOOKUP(E18,'Normative data'!$Y$3:$Y$6,'Normative data'!$Z$3:$AG$6,,-1),'Normative data'!$Z$2:$AG$2,"Not Found",-1))} -> Incomplete | CU18: {=_xlfn.XLOOKUP(CS18&CT18,(VLOOKUP!$A$3:$A$250)&(VLOOKUP!$B$3:$B$250),VLOOKUP!$C$3:$C$250,"Incomplete",-1)} -> Incomplete | CV18: {=_xlfn.XLOOKUP(CU18, _xlfn.XLOOKUP(E18, 'Normative data'!$Y$11:$Y$14, 'Normative data'!$Z$11:$AG$14, ,-1), 'Normative data'!$Z$10:$AG$10, "Not Found", -1)} -> Excellent | CW18: {=IF(OR(ISBLANK(CS18),ISBLANK(CT18)),"Incomplete",_xlfn.XLOOKUP(CS18&CT18,VLOOKUP!$A$4:$A$250&VLOOKUP!$B$4:$B$250,VLOOKUP!$D$4:$D$250,"0"))} -> Incomplete
A19: Amy | B19: Aheebwa | C19: Female | D19: 40342 | F19: 9 | G19: 2025 | H19: August | I19: 3 | AY19: =IF(OR(ISBLANK(U19), ISBLANK(AQ19)), "Incomplete", (60.7*AQ19)+(45.3*U19)-2055) -> Incomplete | BA19: =IF(OR(ISBLANK(U19), ISBLANK(AS19)), "Incomplete", (60.7*AS19)+(45.3*U19)-2055) -> Incomplete | BC19: =IF(OR(ISBLANK(U19), ISBLANK(AU19)), "Incomplete", (60.7*AU19)+(45.3*U19)-2055) -> Incomplete | BE19: =IF(OR(ISBLANK(U19), ISBLANK(AW19)), "Incomplete", (60.7*AW19)+(45.3*U19)-2055) -> Incomplete | BG19: 10.2 | BH19: 21 | BI19: =IF(OR(ISBLANK(BG19), ISBLANK(BH19)),"Incomplete",(SUM(BH19-BG19))) -> 10.8 | BW19: =IFERROR(SUM(BQ19+BR19+BS19)/(3*(T19-S19))*100, "Incomplete") -> Incomplete | BX19: =_xlfn.XLOOKUP(BW19,'Normative data'!$V$3:$V$6,'Normative data'!$W$3:$W$6,"Not Found",-1) -> Very low risk | BY19: =IFERROR(SUM(BT19+BU19+BV19)/(3*(T19-S19))*100, "Incomplete") -> Incomplete | BZ19: =_xlfn.XLOOKUP(BY19,'Normative data'!$V$3:$V$6,'Normative data'!$W$3:$W$6,"Not Found",-1) -> Very low risk | CH19: =_xlfn.XLOOKUP(CG19, 'Normative data'!$S$9:$S$15,'Normative data'!$T$9:$T$15, "Not Found", -1) -> not completed | CJ19: =_xlfn.XLOOKUP(CI19, 'Normative data'!$S$9:$S$15, 'Normative data'!$T$9:$T$15, "Not Found", -1) -> not completed | CK19: 2.63 | CL19: 3.8 | CN19: 8.69 | CO19: 5.75 | CR19: {=IF(OR(ISBLANK(E19),ISBLANK(CQ19)),"Incomplete",_xlfn.XLOOKUP(CQ19,_xlfn.XLOOKUP(E19,'Normative data'!$Y$3:$Y$6,'Normative data'!$Z$3:$AG$6,,-1),'Normative data'!$Z$2:$AG$2,"Not Found",-1))} -> Incomplete | CU19: {=_xlfn.XLOOKUP(CS19&CT19,(VLOOKUP!$A$3:$A$250)&(VLOOKUP!$B$3:$B$250),VLOOKUP!$C$3:$C$250,"Incomplete",-1)} -> Incomplete | CV19: {=_xlfn.XLOOKUP(CU19, _xlfn.XLOOKUP(E19, 'Normative data'!$Y$11:$Y$14, 'Normative data'!$Z$11:$AG$14, ,-1), 'Normative data'!$Z$10:$AG$10, "Not Found", -1)} -> Excellent | CW19: {=IF(OR(ISBLANK(CS19),ISBLANK(CT19)),"Incomplete",_xlfn.XLOOKUP(CS19&CT19,VLOOKUP!$A$4:$A$250&VLOOKUP!$B$4:$B$250,VLOOKUP!$D$4:$D$250,"0"))} -> Incomplete
A20: Holly | B20: Ahlschlager | C20: Female | F20: 11 | G20: 2025 | H20: August | I20: 3 | AY20: =IF(OR(ISBLANK(U20), ISBLANK(AQ20)), "Incomplete", (60.7*AQ20)+(45.3*U20)-2055) -> Incomplete | BA20: =IF(OR(ISBLANK(U20), ISBLANK(AS20)), "Incomplete", (60.7*AS20)+(45.3*U20)-2055) -> Incomplete | BC20: =IF(OR(ISBLANK(U20), ISBLANK(AU20)), "Incomplete", (60.7*AU20)+(45.3*U20)-2055) -> Incomplete | BE20: =IF(OR(ISBLANK(U20), ISBLANK(AW20)), "Incomplete", (60.7*AW20)+(45.3*U20)-2055) -> Incomplete | BG20: 14 | BH20: 29 | BI20: =IF(OR(ISBLANK(BG20), ISBLANK(BH20)),"Incomplete",(SUM(BH20-BG20))) -> 15 | BW20: =IFERROR(SUM(BQ20+BR20+BS20)/(3*(T20-S20))*100, "Incomplete") -> Incomplete | BX20: =_xlfn.XLOOKUP(BW20,'Normative data'!$V$3:$V$6,'Normative data'!$W$3:$W$6,"Not Found",-1) -> Very low risk | BY20: =IFERROR(SUM(BT20+BU20+BV20)/(3*(T20-S20))*100, "Incomplete") -> Incomplete | BZ20: =_xlfn.XLOOKUP(BY20,'Normative data'!$V$3:$V$6,'Normative data'!$W$3:$W$6,"Not Found",-1) -> Very low risk | CE20: 12 | CH20: =_xlfn.XLOOKUP(CG20, 'Normative data'!$S$9:$S$15,'Normative data'!$T$9:$T$15, "Not Found", -1) -> not completed | CJ20: =_xlfn.XLOOKUP(CI20, 'Normative data'!$S$9:$S$15, 'Normative data'!$T$9:$T$15, "Not Found", -1) -> not completed | CR20: {=IF(OR(ISBLANK(E20),ISBLANK(CQ20)),"Incomplete",_xlfn.XLOOKUP(CQ20,_xlfn.XLOOKUP(E20,'Normative data'!$Y$3:$Y$6,'Normative data'!$Z$3:$AG$6,,-1),'Normative data'!$Z$2:$AG$2,"Not Found",-1))} -> Incomplete | CU20: {=_xlfn.XLOOKUP(CS20&CT20,(VLOOKUP!$A$3:$A$250)&(VLOOKUP!$B$3:$B$250),VLOOKUP!$C$3:$C$250,"Incomplete",-1)} -> Incomplete | CV20: {=_xlfn.XLOOKUP(CU20, _xlfn.XLOOKUP(E20, 'Normative data'!$Y$11:$Y$14, 'Normative data'!$Z$11:$AG$14, ,-1), 'Normative data'!$Z$10:$AG$10, "Not Found", -1)} -> Excellent | CW20: {=IF(OR(ISBLANK(CS20),ISBLANK(CT20)),"Incomplete",_xlfn.XLOOKUP(CS20&CT20,VLOOKUP!$A$4:$A$250&VLOOKUP!$B$4:$B$250,VLOOKUP!$D$4:$D$250,"0"))} -> Incomplete
A21: van der Vaart | B21: Aila | C21: Female | D21: 41258 | E21: 13.5 | F21: 8A | G21: 2026 | I21: 2 | J21: Hockey | K21: U/14 C | S21: 82.8 | T21: 164.8 | U21: 50.4 | V21: 27.9 | W21: 12.3 | X21: 38.1 | Y21: 20.5 | Z21: 18.6 | AA21: 24.4 | AB21: 6.07 | AC21: 104.3 | AD21: 6.07 | AE21: 104.2 | AF21: 2.1 | AG21: 85.7 | AH21: 2.1 | AI21: 85.6 | AJ21: 339.5 | AK21: 340 | AL21: 306 | AM21: 307.3 | AN21: 98 | AQ21: 19.3 | AR21: 0.397 | AS21: 26.7 | AT21: 0.467 | AU21: 11.3 | AV21: 0.304 | AW21: 13.1 | AX21: 0.327 | AY21: =IF(OR(ISBLANK(U21), ISBLANK(AQ21)), "Incomplete", (60.7*AQ21)+(45.3*U21)-2055) -> 1399.63 | BA21: =IF(OR(ISBLANK(U21), ISBLANK(AS21)), "Incomplete", (60.7*AS21)+(45.3*U21)-2055) -> 1848.81 | BC21: =IF(OR(ISBLANK(U21), ISBLANK(AU21)), "Incomplete", (60.7*AU21)+(45.3*U21)-2055) -> 914.03 | BE21: =IF(OR(ISBLANK(U21), ISBLANK(AW21)), "Incomplete", (60.7*AW21)+(45.3*U21)-2055) -> 1023.29 | BG21: 9.5 | BH21: 35.9 | BI21: =IF(OR(ISBLANK(BG21), ISBLANK(BH21)),"Incomplete",(SUM(BH21-BG21))) -> 26.4 | BK21: 9 | BM21: 8 | BO21: 46.5 | BP21: 46.5 | BQ21: 94 | BR21: 82 | BS21: 76 | BT21: 84 | BU21: 78 | BV21: 70 | BW21: =IFERROR(SUM(BQ21+BR21+BS21)/(3*(T21-S21))*100, "Incomplete") -> 102.43902 | BX21: =_xlfn.XLOOKUP(BW21,'Normative data'!$V$3:$V$6,'Normative data'!$W$3:$W$6,"Not Found",-1) -> Low risk | BY21: =IFERROR(SUM(BT21+BU21+BV21)/(3*(T21-S21))*100, "Incomplete") -> 94.308943 | BZ21: =_xlfn.XLOOKUP(BY21,'Normative data'!$V$3:$V$6,'Normative data'!$W$3:$W$6,"Not Found",-1) -> High risk | CA21: 31 | CE21: 19 | CH21: =_xlfn.XLOOKUP(CG21, 'Normative data'!$S$9:$S$15,'Normative data'!$T$9:$T$15, "Not Found", -1) -> not completed | CJ21: =_xlfn.XLOOKUP(CI21, 'Normative data'!$S$9:$S$15, 'Normative data'!$T$9:$T$15, "Not Found", -1) -> not completed | CK21: 2.25 | CL21: 4.44 | CN21: 6.94 | CO21: 7.2 | CR21: {=IF(OR(ISBLANK(E21),ISBLANK(CQ21)),"Incomplete",_xlfn.XLOOKUP(CQ21,_xlfn.XLOOKUP(E21,'Normative data'!$Y$3:$Y$6,'Normative data'!$Z$3:$AG$6,,-1),'Normative data'!$Z$2:$AG$2,"Not Found",-1))} -> Incomplete | CU21: {=_xlfn.XLOOKUP(CS21&CT21,(VLOOKUP!$A$3:$A$250)&(VLOOKUP!$B$3:$B$250),VLOOKUP!$C$3:$C$250,"Incomplete",-1)} -> Incomplete | CV21: {=_xlfn.XLOOKUP(CU21, _xlfn.XLOOKUP(E21, 'Normative data'!$Y$11:$Y$14, 'Normative data'!$Z$11:$AG$14, ,-1), 'Normative data'!$Z$10:$AG$10, "Not Found", -1)} -> Excellent | CW21: {=IF(OR(ISBLANK(CS21),ISBLANK(CT21)),"Incomplete",_xlfn.XLOOKUP(CS21&CT21,VLOOKUP!$A$4:$A$250&VLOOKUP!$B$4:$B$250,VLOOKUP!$D$4:$D$250,"0"))} -> Incomplete
A22: Sienna | B22: Airey | C22: Female | D22: 40259 | F22: 9 | G22: 2025 | H22: January | I22: 1 | AY22: =IF(OR(ISBLANK(U22), ISBLANK(AQ22)), "Incomplete", (60.7*AQ22)+(45.3*U22)-2055) -> Incomplete | BA22: =IF(OR(ISBLANK(U22), ISBLANK(AS22)), "Incomplete", (60.7*AS22)+(45.3*U22)-2055) -> Incomplete | BC22: =IF(OR(ISBLANK(U22), ISBLANK(AU22)), "Incomplete", (60.7*AU22)+(45.3*U22)-2055) -> Incomplete | BE22: =IF(OR(ISBLANK(U22), ISBLANK(AW22)), "Incomplete", (60.7*AW22)+(45.3*U22)-2055) -> Incomplete | BG22: 16 | BH22: 45.5 | BI22: =IF(OR(ISBLANK(BG22), ISBLANK(BH22)),"Incomplete",(SUM(BH22-BG22))) -> 29.5 | BW22: =IFERROR(SUM(BQ22+BR22+BS22)/(3*(T22-S22))*100, "Incomplete") -> Incomplete | BX22: =_xlfn.XLOOKUP(BW22,'Normative data'!$V$3:$V$6,'Normative data'!$W$3:$W$6,"Not Found",-1) -> Very low risk | BY22: =IFERROR(SUM(BT22+BU22+BV22)/(3*(T22-S22))*100, "Incomplete") -> Incomplete | BZ22: =_xlfn.XLOOKUP(BY22,'Normative data'!$V$3:$V$6,'Normative data'!$W$3:$W$6,"Not Found",-1) -> Very low risk | CE22: 13 | CH22: =_xlfn.XLOOKUP(CG22, 'Normative data'!$S$9:$S$15,'Normative data'!$T$9:$T$15, "Not Found", -1) -> not completed | CJ22: =_xlfn.XLOOKUP(CI22, 'Normative data'!$S$9:$S$15, 'Normative data'!$T$9:$T$15, "Not Found", -1) -> not completed | CK22: 2.09 | CL22: 4.78 | CN22: 6.8 | CO22: 7.35 | CR22: {=IF(OR(ISBLANK(E22),ISBLANK(CQ22)),"Incomplete",_xlfn.XLOOKUP(CQ22,_xlfn.XLOOKUP(E22,'Normative data'!$Y$3:$Y$6,'Normative data'!$Z$3:$AG$6,,-1),'Normative data'!$Z$2:$AG$2,"Not Found",-1))} -> Incomplete | CU22: {=_xlfn.XLOOKUP(CS22&CT22,(VLOOKUP!$A$3:$A$250)&(VLOOKUP!$B$3:$B$250),VLOOKUP!$C$3:$C$250,"Incomplete",-1)} -> Incomplete | CV22: {=_xlfn.XLOOKUP(CU22, _xlfn.XLOOKUP(E22, 'Normative data'!$Y$11:$Y$14, 'Normative data'!$Z$11:$AG$14, ,-1), 'Normative data'!$Z$10:$AG$10, "Not Found", -1)} -> Excellent | CW22: {=IF(OR(ISBLANK(CS22),ISBLANK(CT22)),"Incomplete",_xlfn.XLOOKUP(CS22&CT22,VLOOKUP!$A$4:$A$250&VLOOKUP!$B$4:$B$250,VLOOKUP!$D$4:$D$250,"0"))} -> Incomplete
A23: Sienna | B23: Airey | C23: Female | F23: 9 | G23: 2025 | H23: August | I23: 3 | AY23: =IF(OR(ISBLANK(U23), ISBLANK(AQ23)), "Incomplete", (60.7*AQ23)+(45.3*U23)-2055) -> Incomplete | BA23: =IF(OR(ISBLANK(U23), ISBLANK(AS23)), "Incomplete", (60.7*AS23)+(45.3*U23)-2055) -> Incomplete | BC23: =IF(OR(ISBLANK(U23), ISBLANK(AU23)), "Incomplete", (60.7*AU23)+(45.3*U23)-2055) -> Incomplete | BE23: =IF(OR(ISBLANK(U23), ISBLANK(AW23)), "Incomplete", (60.7*AW23)+(45.3*U23)-2055) -> Incomplete | BI23: =IF(OR(ISBLANK(BG23), ISBLANK(BH23)),"Incomplete",(SUM(BH23-BG23))) -> Incomplete | BW23: =IFERROR(SUM(BQ23+BR23+BS23)/(3*(T23-S23))*100, "Incomplete") -> Incomplete | BX23: =_xlfn.XLOOKUP(BW23,'Normative data'!$V$3:$V$6,'Normative data'!$W$3:$W$6,"Not Found",-1) -> Very low risk | BY23: =IFERROR(SUM(BT23+BU23+BV23)/(3*(T23-S23))*100, "Incomplete") -> Incomplete | BZ23: =_xlfn.XLOOKUP(BY23,'Normative data'!$V$3:$V$6,'Normative data'!$W$3:$W$6,"Not Found",-1) -> Very low risk | CH23: =_xlfn.XLOOKUP(CG23, 'Normative data'!$S$9:$S$15,'Normative data'!$T$9:$T$15, "Not Found", -1) -> not completed | CJ23: =_xlfn.XLOOKUP(CI23, 'Normative data'!$S$9:$S$15, 'Normative data'!$T$9:$T$15, "Not Found", -1) -> not completed | CK23: 2.17 | CL23: 4.61 | CN23: 6.98 | CO23: 7.16 | CR23: {=IF(OR(ISBLANK(E23),ISBLANK(CQ23)),"Incomplete",_xlfn.XLOOKUP(CQ23,_xlfn.XLOOKUP(E23,'Normative data'!$Y$3:$Y$6,'Normative data'!$Z$3:$AG$6,,-1),'Normative data'!$Z$2:$AG$2,"Not Found",-1))} -> Incomplete | CU23: {=_xlfn.XLOOKUP(CS23&CT23,(VLOOKUP!$A$3:$A$250)&(VLOOKUP!$B$3:$B$250),VLOOKUP!$C$3:$C$250,"Incomplete",-1)} -> Incomplete | CV23: {=_xlfn.XLOOKUP(CU23, _xlfn.XLOOKUP(E23, 'Normative data'!$Y$11:$Y$14, 'Normative data'!$Z$11:$AG$14, ,-1), 'Normative data'!$Z$10:$AG$10, "Not Found", -1)} -> Excellent | CW23: {=IF(OR(ISBLANK(CS23),ISBLANK(CT23)),"Incomplete",_xlfn.XLOOKUP(CS23&CT23,VLOOKUP!$A$4:$A$250&VLOOKUP!$B$4:$B$250,VLOOKUP!$D$4:$D$250,"0"))} -> Incomplete
A24: Hendricks | B24: Aisha | C24: Female | F24: 11E | G24: 2026 | I24: 2 | J24: Hockey | K24: 2nd | AY24: =IF(OR(ISBLANK(U24), ISBLANK(AQ24)), "Incomplete", (60.7*AQ24)+(45.3*U24)-2055) -> Incomplete | BA24: =IF(OR(ISBLANK(U24), ISBLANK(AS24)), "Incomplete", (60.7*AS24)+(45.3*U24)-2055) -> Incomplete | BC24: =IF(OR(ISBLANK(U24), ISBLANK(AU24)), "Incomplete", (60.7*AU24)+(45.3*U24)-2055) -> Incomplete | BE24: =IF(OR(ISBLANK(U24), ISBLANK(AW24)), "Incomplete", (60.7*AW24)+(45.3*U24)-2055) -> Incomplete | BI24: =IF(OR(ISBLANK(BG24), ISBLANK(BH24)),"Incomplete",(SUM(BH24-BG24))) -> Incomplete | BQ24: 75 | BR24: 77 | BS24: 73 | BT24: 75 | BU24: 74 | BV24: 71 | BW24: =IFERROR(SUM(BQ24+BR24+BS24)/(3*(T24-S24))*100, "Incomplete") -> Incomplete | BX24: =_xlfn.XLOOKUP(BW24,'Normative data'!$V$3:$V$6,'Normative data'!$W$3:$W$6,"Not Found",-1) -> Very low risk | BY24: =IFERROR(SUM(BT24+BU24+BV24)/(3*(T24-S24))*100, "Incomplete") -> Incomplete | BZ24: =_xlfn.XLOOKUP(BY24,'Normative data'!$V$3:$V$6,'Normative data'!$W$3:$W$6,"Not Found",-1) -> Very low risk | CA24: 29 | CE24: 12 | CG24: 19.6 | CH24: =_xlfn.XLOOKUP(CG24, 'Normative data'!$S$9:$S$15,'Normative data'!$T$9:$T$15, "Not Found", -1) -> Average | CI24: 19.8 | CJ24: =_xlfn.XLOOKUP(CI24, 'Normative data'!$S$9:$S$15, 'Normative data'!$T$9:$T$15, "Not Found", -1) -> Average | CK24: 2.24 | CL24: 4.46 | CN24: 6.92 | CO24: 7.23 | CR24: {=IF(OR(ISBLANK(E24),ISBLANK(CQ24)),"Incomplete",_xlfn.XLOOKUP(CQ24,_xlfn.XLOOKUP(E24,'Normative data'!$Y$3:$Y$6,'Normative data'!$Z$3:$AG$6,,-1),'Normative data'!$Z$2:$AG$2,"Not Found",-1))} -> Incomplete | CU24: {=_xlfn.XLOOKUP(CS24&CT24,(VLOOKUP!$A$3:$A$250)&(VLOOKUP!$B$3:$B$250),VLOOKUP!$C$3:$C$250,"Incomplete",-1)} -> Incomplete | CV24: {=_xlfn.XLOOKUP(CU24, _xlfn.XLOOKUP(E24, 'Normative data'!$Y$11:$Y$14, 'Normative data'!$Z$11:$AG$14, ,-1), 'Normative data'!$Z$10:$AG$10, "Not Found", -1)} -> Excellent | CW24: {=IF(OR(ISBLANK(CS24),ISBLANK(CT24)),"Incomplete",_xlfn.XLOOKUP(CS24&CT24,VLOOKUP!$A$4:$A$250&VLOOKUP!$B$4:$B$250,VLOOKUP!$D$4:$D$250,"0"))} -> Incomplete
A25: Wareham | B25: Alana | C25: Female | D25: 40536 | F25: 9I | G25: 2026 | I25: 2 | J25: Hockey | K25: U/16 C | S25: 80.3 | T25: 165.2 | U25: 53.3 | V25: 31 | W25: 10.9 | X25: 42.4 | Y25: 23.1 | Z25: 19.5 | AA25: 20.4 | AB25: 6.52 | AC25: 105.9 | AD25: 6.53 | AE25: 105.9 | AF25: 1.8 | AG25: 73.1 | AH25: 1.8 | AI25: 72.7 | AJ25: 306.7 | AK25: 304.6 | AL25: 272 | AM25: 272.6 | AN25: 99 | AO25: 0.81 | AP25: 6.2 | AY25: =IF(OR(ISBLANK(U25), ISBLANK(AQ25)), "Incomplete", (60.7*AQ25)+(45.3*U25)-2055) -> Incomplete | BA25: =IF(OR(ISBLANK(U25), ISBLANK(AS25)), "Incomplete", (60.7*AS25)+(45.3*U25)-2055) -> Incomplete | BC25: =IF(OR(ISBLANK(U25), ISBLANK(AU25)), "Incomplete", (60.7*AU25)+(45.3*U25)-2055) -> Incomplete | BE25: =IF(OR(ISBLANK(U25), ISBLANK(AW25)), "Incomplete", (60.7*AW25)+(45.3*U25)-2055) -> Incomplete | BG25: 16 | BH25: 42.5 | BI25: =IF(OR(ISBLANK(BG25), ISBLANK(BH25)),"Incomplete",(SUM(BH25-BG25))) -> 26.5 | BO25: 43.2 | BP25: 43.2 | BQ25: 83 | BR25: 85 | BS25: 80 | BT25: 80 | BU25: 81 | BV25: 75 | BW25: =IFERROR(SUM(BQ25+BR25+BS25)/(3*(T25-S25))*100, "Incomplete") -> 97.369454 | BX25: =_xlfn.XLOOKUP(BW25,'Normative data'!$V$3:$V$6,'Normative data'!$W$3:$W$6,"Not Found",-1) -> Low risk | BY25: =IFERROR(SUM(BT25+BU25+BV25)/(3*(T25-S25))*100, "Incomplete") -> 92.658029 | BZ25: =_xlfn.XLOOKUP(BY25,'Normative data'!$V$3:$V$6,'Normative data'!$W$3:$W$6,"Not Found",-1) -> High risk | CA25: 30 | CE25: 20 | CH25: =_xlfn.XLOOKUP(CG25, 'Normative data'!$S$9:$S$15,'Normative data'!$T$9:$T$15, "Not Found", -1) -> not completed | CJ25: =_xlfn.XLOOKUP(CI25, 'Normative data'!$S$9:$S$15, 'Normative data'!$T$9:$T$15, "Not Found", -1) -> not completed | CK25: 2.4 | CL25: 4.17 | CN25: 7.73 | CO25: 6.47 | CQ25: 3.1 | CR25: {=IF(OR(ISBLANK(E25),ISBLANK(CQ25)),"Incomplete",_xlfn.XLOOKUP(CQ25,_xlfn.XLOOKUP(E25,'Normative data'!$Y$3:$Y$6,'Normative data'!$Z$3:$AG$6,,-1),'Normative data'!$Z$2:$AG$2,"Not Found",-1))} -> Incomplete | CS25: 3 | CT25: 1 | CU25: {=_xlfn.XLOOKUP(CS25&CT25,(VLOOKUP!$A$3:$A$250)&(VLOOKUP!$B$3:$B$250),VLOOKUP!$C$3:$C$250,"Incomplete",-1)} -> 320 | CV25: {=_xlfn.XLOOKUP(CU25, _xlfn.XLOOKUP(E25, 'Normative data'!$Y$11:$Y$14, 'Normative data'!$Z$11:$AG$14, ,-1), 'Normative data'!$Z$10:$AG$10, "Not Found", -1)} -> Very poor | CW25: {=IF(OR(ISBLANK(CS25),ISBLANK(CT25)),"Incomplete",_xlfn.XLOOKUP(CS25&CT25,VLOOKUP!$A$4:$A$250&VLOOKUP!$B$4:$B$250,VLOOKUP!$D$4:$D$250,"0"))} -> 23
A26: Burns | B26: Alexa Ella | C26: Female | D26: 41217 | E26: 14.1 | F26: 8D | G26: 2026 | I26: 2 | J26: Hockey | K26: U/14 B | S26: 88.4 | T26: 170.1 | U26: 64.4 | V26: 34.1 | W26: 17.8 | X26: 46.6 | Y26: 25.5 | Z26: 22.3 | AA26: 27.6 | AB26: 7.52 | AC26: 103.5 | AD26: 7.59 | AE26: 104.5 | AF26: 2.9 | AG26: 110.3 | AH26: 2.9 | AI26: 110.6 | AJ26: 280.8 | AK26: 274.4 | AL26: 253.7 | AM26: 247.3 | AN26: 105 | AO26: 0.83 | AP26: 6.7 | AQ26: 15 | AR26: 0.35 | AS26: 18.3 | AT26: 0.386 | AU26: 9.3 | AV26: 0.275 | AW26: 8.5 | AX26: 0.265 | AY26: =IF(OR(ISBLANK(U26), ISBLANK(AQ26)), "Incomplete", (60.7*AQ26)+(45.3*U26)-2055) -> 1772.82 | BA26: =IF(OR(ISBLANK(U26), ISBLANK(AS26)), "Incomplete", (60.7*AS26)+(45.3*U26)-2055) -> 1973.13 | BC26: =IF(OR(ISBLANK(U26), ISBLANK(AU26)), "Incomplete", (60.7*AU26)+(45.3*U26)-2055) -> 1426.83 | BE26: =IF(OR(ISBLANK(U26), ISBLANK(AW26)), "Incomplete", (60.7*AW26)+(45.3*U26)-2055) -> 1378.27 | BG26: 10 | BH26: 42 | BI26: =IF(OR(ISBLANK(BG26), ISBLANK(BH26)),"Incomplete",(SUM(BH26-BG26))) -> 32 | BK26: 8 | BM26: 7.5 | BO26: 52.5 | BP26: 52 | BQ26: 93 | BR26: 86 | BS26: 79 | BT26: 94 | BU26: 81 | BV26: 74 | BW26: =IFERROR(SUM(BQ26+BR26+BS26)/(3*(T26-S26))*100, "Incomplete") -> 105.26316 | BX26: =_xlfn.XLOOKUP(BW26,'Normative data'!$V$3:$V$6,'Normative data'!$W$3:$W$6,"Not Found",-1) -> Low risk | BY26: =IFERROR(SUM(BT26+BU26+BV26)/(3*(T26-S26))*100, "Incomplete") -> 101.59119 | BZ26: =_xlfn.XLOOKUP(BY26,'Normative data'!$V$3:$V$6,'Normative data'!$W$3:$W$6,"Not Found",-1) -> Low risk | CA26: 36 | CE26: 13 | CG26: 18.26 | CH26: =_xlfn.XLOOKUP(CG26, 'Normative data'!$S$9:$S$15,'Normative data'!$T$9:$T$15, "Not Found", -1) -> Average | CI26: 18.36 | CJ26: =_xlfn.XLOOKUP(CI26, 'Normative data'!$S$9:$S$15, 'Normative data'!$T$9:$T$15, "Not Found", -1) -> Average | CK26: 3.26 | CL26: 3.07 | CN26: 7.81 | CO26: 6.4 | CQ26: 9.7 | CR26: {=IF(OR(ISBLANK(E26),ISBLANK(CQ26)),"Incomplete",_xlfn.XLOOKUP(CQ26,_xlfn.XLOOKUP(E26,'Normative data'!$Y$3:$Y$6,'Normative data'!$Z$3:$AG$6,,-1),'Normative data'!$Z$2:$AG$2,"Not Found",-1))} -> Very good | CS26: 9 | CT26: 7 | CU26: {=_xlfn.XLOOKUP(CS26&CT26,(VLOOKUP!$A$3:$A$250)&(VLOOKUP!$B$3:$B$250),VLOOKUP!$C$3:$C$250,"Incomplete",-1)} -> 1580 | CV26: {=_xlfn.XLOOKUP(CU26, _xlfn.XLOOKUP(E26, 'Normative data'!$Y$11:$Y$14, 'Normative data'!$Z$11:$AG$14, ,-1), 'Normative data'!$Z$10:$AG$10, "Not Found", -1)} -> Good | CW26: {=IF(OR(ISBLANK(CS26),ISBLANK(CT26)),"Incomplete",_xlfn.XLOOKUP(CS26&CT26,VLOOKUP!$A$4:$A$250&VLOOKUP!$B$4:$B$250,VLOOKUP!$D$4:$D$250,"0"))} -> 46
A27: Goosen | B27: Alexandra | C27: Female | F27: 10E | G27: 2026 | I27: 2 | S27: 87.1 | T27: 167.5 | AY27: =IF(OR(ISBLANK(U27), ISBLANK(AQ27)), "Incomplete", (60.7*AQ27)+(45.3*U27)-2055) -> Incomplete | BA27: =IF(OR(ISBLANK(U27), ISBLANK(AS27)), "Incomplete", (60.7*AS27)+(45.3*U27)-2055) -> Incomplete | BC27: =IF(OR(ISBLANK(U27), ISBLANK(AU27)), "Incomplete", (60.7*AU27)+(45.3*U27)-2055) -> Incomplete | BE27: =IF(OR(ISBLANK(U27), ISBLANK(AW27)), "Incomplete", (60.7*AW27)+(45.3*U27)-2055) -> Incomplete | BG27: 13.9 | BH27: 34.3 | BI27: =IF(OR(ISBLANK(BG27), ISBLANK(BH27)),"Incomplete",(SUM(BH27-BG27))) -> 20.4 | BW27: =IFERROR(SUM(BQ27+BR27+BS27)/(3*(T27-S27))*100, "Incomplete") -> 0 | BX27: =_xlfn.XLOOKUP(BW27,'Normative data'!$V$3:$V$6,'Normative data'!$W$3:$W$6,"Not Found",-1) -> Not completed | BY27: =IFERROR(SUM(BT27+BU27+BV27)/(3*(T27-S27))*100, "Incomplete") -> 0 | BZ27: =_xlfn.XLOOKUP(BY27,'Normative data'!$V$3:$V$6,'Normative data'!$W$3:$W$6,"Not Found",-1) -> Not completed | CA27: 32 | CE27: 14 | CG27: 19.68 | CH27: =_xlfn.XLOOKUP(CG27, 'Normative data'!$S$9:$S$15,'Normative data'!$T$9:$T$15, "Not Found", -1) -> Average | CI27: 19.99 | CJ27: =_xlfn.XLOOKUP(CI27, 'Normative data'!$S$9:$S$15, 'Normative data'!$T$9:$T$15, "Not Found", -1) -> Average | CK27: 2.46 | CL27: 4.07 | CN27: 7.91 | CO27: 6.32 | CR27: {=IF(OR(ISBLANK(E27),ISBLANK(CQ27)),"Incomplete",_xlfn.XLOOKUP(CQ27,_xlfn.XLOOKUP(E27,'Normative data'!$Y$3:$Y$6,'Normative data'!$Z$3:$AG$6,,-1),'Normative data'!$Z$2:$AG$2,"Not Found",-1))} -> Incomplete | CU27: {=_xlfn.XLOOKUP(CS27&CT27,(VLOOKUP!$A$3:$A$250)&(VLOOKUP!$B$3:$B$250),VLOOKUP!$C$3:$C$250,"Incomplete",-1)} -> Incomplete | CV27: {=_xlfn.XLOOKUP(CU27, _xlfn.XLOOKUP(E27, 'Normative data'!$Y$11:$Y$14, 'Normative data'!$Z$11:$AG$14, ,-1), 'Normative data'!$Z$10:$AG$10, "Not Found", -1)} -> Excellent | CW27: {=IF(OR(ISBLANK(CS27),ISBLANK(CT27)),"Incomplete",_xlfn.XLOOKUP(CS27&CT27,VLOOKUP!$A$4:$A$250&VLOOKUP!$B$4:$B$250,VLOOKUP!$D$4:$D$250,"0"))} -> Incomplete
